Workbook
Name LLPStateList: 'LLP Stamp Duty'!$B$6:$B$41

Sheet LLP Calculator
B2: LLP Incorporation Cost Calculator — MCA Fee + State Stamp Duty
B3: Limited Liability Partnership Act, 2008 and the LLP Rules, 2009 (Table of Fees), read with the State Stamp Acts | All amounts in Indian Rupees
B4: Blue figures on a yellow fill are inputs — edit those only. Green = read from another tab. Black = computed here.
B5: INPUTS | D5: Edit the yellow cells only
B6: Total capital contribution — all partners combined (Rs.) | C6: 500000
B7: State / Union Territory of registered office | C7: Delhi | H7: # | I7: Item | J7: Count / Nos. | K7: Amount (INR)
B8: Number of designated partners | C8: 2 | E8: Minimum of two under section 7 of the LLP Act, 2008. | H8: Government Fees Reimbursement
B9: Designated partners requiring a fresh DPIN / DIN | C9: 0 | E9: Count only partners who do not already hold a DIN or DPIN. Leave at nil if DPIN for the first two is absorbed in the FiLLiP fee. | H9: 1 | I9: MCA Fee for LLP Incorporation | K9: 2000
B10: Include name reservation (RUN-LLP / FiLLiP Part A)? | C10: Yes | H10: 2 | I10: PAN and TAN Fees | K10: 143
B11: Number of Digital Signature Certificates required | C11: 2 | H11: 3 | I11: MCA Fees for Name Approval | K11: 200
B12: Professional fee — CAA (Rs.) | C12: 3499 | E12: Fee carried from the source calculator. The second pricing block in that file quoted ₹3,950 — settle which applies. | H12: 4 | I12: LLP Deed Stamp Duty | K12: 5000
B13: Helper — fee band row on 'MCA Fees LLP' | C13: =MATCH($C$6,'MCA Fees LLP'!$B$6:$B$9,1) -> 2 | J13: Sub-Total | K13: 7343
B14: Helper — State row on 'LLP Stamp Duty' | C14: =MATCH($C$7,LLPStateList,0) -> 9 | H14: Professional Fees & Other OPE
H15: 1 | I15: Professional Fees (Including LLP Deed drafting) | J15: 2 | K15: 3950
B16: A. MCA STATUTORY FEE | D16: LLP Rules, 2009 — Table of Fees | H16: 2 | I16: Franking, Notary, Courier etc | K16: 1950
B17: Name reservation (RUN-LLP / FiLLiP Part A) | C17: =IF($C$10="Yes",'MCA Fees LLP'!$D$12,0) -> 200 | D17: Annexure A | E17: Flat statutory fee per application. | H17: 3 | I17: Digital Signature Certificates (DSCs) | J17: 2 | K17: 4200
B18: FiLLiP incorporation fee | C18: =INDEX('MCA Fees LLP'!$D$6:$D$9,$C$13) -> 2000 | D18: =INDEX('MCA Fees LLP'!$C$6:$C$9,$C$13) -> ₹1,00,001 to ₹500000 | E18: Band determined by total capital contribution. | J18: Sub-Total | K18: 10100
B19: Form 3 filing fee — LLP agreement | C19: =INDEX('MCA Fees LLP'!$E$6:$E$9,$C$13) -> 100 | D19: =INDEX('MCA Fees LLP'!$C$6:$C$9,$C$13) -> ₹1,00,001 to ₹500000 | E19: Form 3 must be filed within 30 days of incorporation and requires certification by a practising professional. | J19: GST @18% | K19: 1818
B20: DPIN / DIN allotment | C20: =$C$9*'MCA Fees LLP'!$D$13 -> 0 | D20: Per partner | E20: Nil where every designated partner already holds a DIN or DPIN. | J20: Total Amount | K20: 19261
B21: Sub-total — MCA statutory fee | C21: =SUM(C17:C20) -> 2300
B23: B. STAMP DUTY ON THE LLP AGREEMENT | D23: Executed on stamp paper
B24: Stamp duty on the LLP agreement | C24: =IFERROR(INDEX('LLP Stamp Duty'!$I$6:$I$41,$C$14),"verify") -> 5000 | D24: =$C$7 -> Delhi | E24: =IFERROR(INDEX('LLP Stamp Duty'!$G$6:$G$41,$C$14),"State not found in the table") -> 1% of capital contribution, minimum ₹200, maximum ₹5,000
B25: Sub-total — stamp duty | C25: =IF(ISNUMBER(C24),C24,"verify") -> 5000
B26: Unlike a private limited company, the LLP agreement is a physical instrument executed on stamp paper and is not filed electronically at incorporation. The duty above is therefore a real stamp paper cost, and franking or notarisation in Section D is a separate charge on top of it.
B28: C. OTHER STATUTORY CHARGES
B29: PAN and TAN government fee | C29: ='MCA Fees LLP'!$D$14 -> 143 | D29: Issued on incorporation | E29: Recovered at actuals. Confirm the current charge on the MCA payment screen before quoting.
B30: Sub-total — other statutory charges | C30: =C29 -> 143
B32: D. FRANKING, NOTARY AND OUT-OF-POCKET | D32: Charged at actuals
B33: Franking, stamp paper procurement and notarisation | C33: 1799 | E33: Coordination of stamping and notarisation of the LLP agreement. The source calculator carried ₹1,799 in one block and ₹1,950 in the other — settle which applies.
B34: Courier, printing and other out-of-pocket | C34: 0 | E34: Enter actuals only. Leave at nil where absorbed in the professional fee.
B35: Sub-total — franking, notary and out-of-pocket | C35: =SUM(C33:C34) -> 1799
B36: Recover these charges as a pure-agent disbursement (no GST)? | C36: No | E36: No = absorbed into the CAA fee and charged with GST, which is how the source calculator treated it. Yes = billed at actuals against third-party receipts and excluded from the value of supply under Rule 33 of the CGST Rules, 2017.
B38: E. DIGITAL SIGNATURE CERTIFICATES (DSC)
B39: Number of DSCs required (per input block) | C39: =$C$11 -> 2
B40: Cost per DSC — Class 3, two-year validity (Rs.) | C40: 2000 | E40: Vendor-quoted rate, not a statutory charge. Update to the certifying authority's invoice.
B41: Sub-total — DSC cost | C41: =$C$39*$C$40 -> 4000
B43: F. PROFESSIONAL FEES
B44: Professional fee — incorporation, LLP agreement drafting and Form 3 | C44: =$C$12 -> 3499 | D44: Input block
B45: Manual adjustment to professional fee (+ / −) | C45: 0 | E45: Discounts, scope adders or a negotiated fee. The only professional-fee cell meant to be typed into.
B46: Sub-total — professional fees | C46: =IF(AND(ISNUMBER($C$44),ISNUMBER($C$45)),$C$44+$C$45,"verify") -> 3499
...

Sheet MCA Fees LLP
B2: MCA Statutory Fees — Limited Liability Partnership
B3: Rule 24 read with Annexure A to the Limited Liability Partnership Rules, 2009 (Table of Fees). Fee bands run on TOTAL CAPITAL CONTRIBUTION of all partners combined.
B5: Band lower bound (₹) | C5: Band description | D5: FiLLiP incorporation fee (₹) | E5: Form 3 filing fee (₹) | F5: Source and verification status
B6: 0 | C6: Up to ₹1,00,000 | D6: 500 | E6: 50 | F6: Secondary source, Aug 2026 — confirm once against the MCA fee calculator
B7: 100001 | C7: ₹1,00,001 to ₹500000 | D7: 2000 | E7: 100 | F7: Secondary source, Aug 2026 — confirm once against the MCA fee calculator
B8: 500001 | C8: ₹5,00,001 to ₹1000000 | D8: 4000 | E8: 150 | F8: Secondary source, Aug 2026 — confirm once against the MCA fee calculator
B9: 1000001 | C9: ₹10,00,000 and above | D9: 5000 | E9: 200 | F9: Secondary source, Aug 2026 — confirm once against the MCA fee calculator
B11: FIXED STATUTORY FEES
B12: Name reservation — RUN-LLP / FiLLiP Part A | D12: 200 | F12: Flat statutory fee per application.
B13: DPIN / DIN allotment — per designated partner without an existing DIN | D13: 500 | F13: Confirm whether DPIN for the first two designated partners is absorbed in the FiLLiP fee. Applied only to the count entered on the calculator.
B14: PAN and TAN government fee | D14: 143 | F14: Issued on incorporation. Confirm on the MCA payment screen.
B16: Blue cells on a yellow fill are the rate inputs — edit these when the MCA revises its fees. Band lower bounds must stay in ascending order or the calculator lookup will misread.

Sheet LLP Stamp Duty
B2: Stamp Duty on the LLP Agreement — State and Union Territory Table
B3: Duty on the LLP agreement, computed at the total capital contribution entered on the Calculator tab. Basis codes: PERCENT = rate on contribution subject to a floor and a cap · FLAT = fixed amount · SLAB-KA = Karnataka step scale · VERIFY = the source gives no figure for this State.
B5: State / Union Territory | C5: Basis | D5: Rate or amount | E5: Minimum (₹) | F5: Maximum cap (₹) 0 = none | G5: Rule as stated in the source | H5: Verification status | I5: Duty at entered contribution (₹)
B6: Andaman and Nicobar Islands | C6: VERIFY | D6: 0 | E6: 0 | F6: 0 | G6: Not separately stated in the source | H6: NO FIGURE in source — obtain the State rate before quoting | I6: =IF($C6="VERIFY","verify",IF($C6="FLAT",$D6,IF($C6="PERCENT",MIN(IF($F6=0,1000000000,$F6),MAX('LLP Calculator'!$C$6*$D6,$E6)),IF($C6="SLAB-KA",$D6+1000*ROUNDUP(MAX(0,'LLP Calculator'!$C$6-1000000)/500000,0),"verify")))) -> verify
B7: Andhra Pradesh | C7: FLAT | D7: 500 | E7: 0 | F7: 0 | G7: Flat ₹500 for any capital amount | H7: Secondary source — verify against the State schedule | I7: =IF($C7="VERIFY","verify",IF($C7="FLAT",$D7,IF($C7="PERCENT",MIN(IF($F7=0,1000000000,$F7),MAX('LLP Calculator'!$C$6*$D7,$E7)),IF($C7="SLAB-KA",$D7+1000*ROUNDUP(MAX(0,'LLP Calculator'!$C$6-1000000)/500000,0),"verify")))) -> 500
B8: Arunachal Pradesh | C8: VERIFY | D8: 0 | E8: 0 | F8: 0 | G8: Grouped under "all other NE States and UTs" with no figure | H8: CONFLICT: CAA source table carried 1% with no cap. Resolve. | I8: =IF($C8="VERIFY","verify",IF($C8="FLAT",$D8,IF($C8="PERCENT",MIN(IF($F8=0,1000000000,$F8),MAX('LLP Calculator'!$C$6*$D8,$E8)),IF($C8="SLAB-KA",$D8+1000*ROUNDUP(MAX(0,'LLP Calculator'!$C$6-1000000)/500000,0),"verify")))) -> verify
B9: Assam | C9: FLAT | D9: 100 | E9: 0 | F9: 0 | G9: Flat ₹100 for any capital amount | H9: Secondary source — verify against the State schedule | I9: =IF($C9="VERIFY","verify",IF($C9="FLAT",$D9,IF($C9="PERCENT",MIN(IF($F9=0,1000000000,$F9),MAX('LLP Calculator'!$C$6*$D9,$E9)),IF($C9="SLAB-KA",$D9+1000*ROUNDUP(MAX(0,'LLP Calculator'!$C$6-1000000)/500000,0),"verify")))) -> 100
B10: Bihar | C10: FLAT | D10: 5000 | E10: 0 | F10: 0 | G10: Flat ₹5,000 for any capital amount | H10: Secondary source — verify against the State schedule | I10: =IF($C10="VERIFY","verify",IF($C10="FLAT",$D10,IF($C10="PERCENT",MIN(IF($F10=0,1000000000,$F10),MAX('LLP Calculator'!$C$6*$D10,$E10)),IF($C10="SLAB-KA",$D10+1000*ROUNDUP(MAX(0,'LLP Calculator'!$C$6-1000000)/500000,0),"verify")))) -> 5000
B11: Chandigarh | C11: VERIFY | D11: 0 | E11: 0 | F11: 0 | G11: Grouped under "all other States and UTs" with no figure | H11: NO FIGURE in source — obtain the State rate before quoting | I11: =IF($C11="VERIFY","verify",IF($C11="FLAT",$D11,IF($C11="PERCENT",MIN(IF($F11=0,1000000000,$F11),MAX('LLP Calculator'!$C$6*$D11,$E11)),IF($C11="SLAB-KA",$D11+1000*ROUNDUP(MAX(0,'LLP Calculator'!$C$6-1000000)/500000,0),"verify")))) -> verify
B12: Chhattisgarh | C12: FLAT | D12: 100 | E12: 0 | F12: 0 | G12: Flat ₹100 for any capital amount | H12: Secondary source — verify against the State schedule | I12: =IF($C12="VERIFY","verify",IF($C12="FLAT",$D12,IF($C12="PERCENT",MIN(IF($F12=0,1000000000,$F12),MAX('LLP Calculator'!$C$6*$D12,$E12)),IF($C12="SLAB-KA",$D12+1000*ROUNDUP(MAX(0,'LLP Calculator'!$C$6-1000000)/500000,0),"verify")))) -> 100
B13: Dadra and Nagar Haveli and Daman and Diu | C13: VERIFY | D13: 0 | E13: 0 | F13: 0 | G13: Not separately stated in the source | H13: NO FIGURE in source — obtain the State rate before quoting | I13: =IF($C13="VERIFY","verify",IF($C13="FLAT",$D13,IF($C13="PERCENT",MIN(IF($F13=0,1000000000,$F13),MAX('LLP Calculator'!$C$6*$D13,$E13)),IF($C13="SLAB-KA",$D13+1000*ROUNDUP(MAX(0,'LLP Calculator'!$C$6-1000000)/500000,0),"verify")))) -> verify
B14: Delhi | C14: PERCENT | D14: 0.01 | E14: 200 | F14: 5000 | G14: 1% of capital contribution, minimum ₹200, maximum ₹5,000 | H14: Earlier "₹200 vs 1%" conflict appears to be floor vs rate — confirm against the Delhi schedule | I14: =IF($C14="VERIFY","verify",IF($C14="FLAT",$D14,IF($C14="PERCENT",MIN(IF($F14=0,1000000000,$F14),MAX('LLP Calculator'!$C$6*$D14,$E14)),IF($C14="SLAB-KA",$D14+1000*ROUNDUP(MAX(0,'LLP Calculator'!$C$6-1000000)/500000,0),"verify")))) -> 5000
B15: Goa | C15: FLAT | D15: 150 | E15: 0 | F15: 0 | G15: Flat ₹150 for any capital amount | H15: Secondary source — verify against the State schedule | I15: =IF($C15="VERIFY","verify",IF($C15="FLAT",$D15,IF($C15="PERCENT",MIN(IF($F15=0,1000000000,$F15),MAX('LLP Calculator'!$C$6*$D15,$E15)),IF($C15="SLAB-KA",$D15+1000*ROUNDUP(MAX(0,'LLP Calculator'!$C$6-1000000)/500000,0),"verify")))) -> 150
B16: Gujarat | C16: PERCENT | D16: 0.01 | E16: 1000 | F16: 10000 | G16: 1% of capital contribution, minimum ₹1,000, maximum ₹10,000 | H16: Secondary source — verify against the State schedule | I16: =IF($C16="VERIFY","verify",IF($C16="FLAT",$D16,IF($C16="PERCENT",MIN(IF($F16=0,1000000000,$F16),MAX('LLP Calculator'!$C$6*$D16,$E16)),IF($C16="SLAB-KA",$D16+1000*ROUNDUP(MAX(0,'LLP Calculator'!$C$6-1000000)/500000,0),"verify")))) -> 5000
B17: Haryana | C17: FLAT | D17: 1000 | E17: 0 | F17: 0 | G17: Flat ₹1,000 for any capital amount | H17: Secondary source — verify against the State schedule | I17: =IF($C17="VERIFY","verify",IF($C17="FLAT",$D17,IF($C17="PERCENT",MIN(IF($F17=0,1000000000,$F17),MAX('LLP Calculator'!$C$6*$D17,$E17)),IF($C17="SLAB-KA",$D17+1000*ROUNDUP(MAX(0,'LLP Calculator'!$C$6-1000000)/500000,0),"verify")))) -> 1000
... B41: West Bengal | C41: FLAT | D41: 150 | E41: 0 | F41: 0 | G41: Flat ₹150 for any capital amount | H41: Secondary source — verify against the State schedule | I41: =IF($C41="VERIFY","verify",IF($C41="FLAT",$D41,IF($C41="PERCENT",MIN(IF($F41=0,1000000000,$F41),MAX('LLP Calculator'!$C$6*$D41,$E41)),IF($C41="SLAB-KA",$D41+1000*ROUNDUP(MAX(0,'LLP Calculator'!$C$6-1000000)/500000,0),"verify")))) -> 150
B43: Source: the 'Stamp Duty Source' tab of this workbook, reproducing the State-wise LLP agreement stamp duty summary supplied with the original CAA calculator. Every row is secondary-sourced and none has been checked against the relevant State Stamp Act. Rows marked in red must be resolved before the figure is put in front of a client.

Sheet Stamp Duty Source
A1: SOURCE OF RECORD — State-wise LLP agreement stamp duty, as supplied
A2: Reproduced unchanged from the 'Stamp duty' tab of the original CAA_LLP_Cost_Calculator file. The 'LLP Stamp Duty' tab is the machine-readable version of this table; where the two differ, this is the source and that is the interpretation.
A4: 1. States with Percentage-Based Rates
A5: These states calculate stamp duty as a direct percentage of the total capital contribution you invest into the LLP. [1, 2]
A6: State / UT | B6: Stamp Duty Rate | C6: Minimum Payable | D6: Maximum Cap
A7: Maharashtra | B7: 1% of capital contribution | C7: ₹500 | D7: ₹15,000
A8: Delhi (NCT) | B8: 1% of capital contribution | C8: ₹200 | D8: ₹5,000
A9: Gujarat | B9: 1% of capital contribution | C9: ₹1,000 | D9: ₹10,000
A10: Madhya Pradesh | B10: 2% of capital contribution | C10: ₹2,000 | D10: ₹10,000
A11: Rajasthan | B11: ~0.5% - 1% based on capital slabs | C11: ₹2,000 | D11: ₹10,000
A12: 2. States with Slab-Based & Flat High Rates
A13: These states charge either a fixed amount depending on your investment bracket or a static high flat fee. [1, 2]
A14: State / UT | B14: Capital Contribution Slab | C14: Total Stamp Duty Payable
A15: Karnataka | B15: • Up to ₹10 Lakhs capital | C15: ₹5,000
B16: • Above ₹10 Lakhs capital | C16: ₹5,000 + ₹1,000 per every additional ₹5 Lakhs
A17: Kerala | B17: Any capital amount | C17: ₹5,000 flat fee
A18: Bihar | B18: Any capital amount | C18: ₹5,000 flat fee
A19: Punjab | B19: Any capital amount | C19: ₹1,000 flat fee
A20: Haryana | B20: Any capital amount | C20: ₹1,000 flat fee
A21: Uttar Pradesh | B21: Any capital amount | C21: ₹750 flat fee
A22: Andhra Pradesh | B22: Any capital amount | C22: ₹500 flat fee
A23: 3. States with Low Nominal / Flat Rates
A24: The remaining states and territories levy a standard flat charge regardless of how much capital is introduced. [1]
A25: State / UT | B25: Total Stamp Duty Payable
A26: Tamil Nadu | B26: ₹300 flat fee
A27: Telangana | B27: ₹100 to ₹300 (depending on local notary/slabs)
A28: Goa | B28: ₹150 flat fee
A29: West Bengal | B29: ₹150 flat fee
A30: Assam | B30: ₹100 flat fee
A31: Himachal Pradesh | B31: ₹100 flat fee
A32: Jammu & Kashmir | B32: ₹100 flat fee
A33: Odisha | B33: ₹100 flat fee
A34: Jharkhand | B34: ₹100 flat fee
A35: Chhattisgarh | B35: ₹100 flat fee
A36: Uttarakhand | B36: ₹100 flat fee
A37: All Other NE States & UTs (Meghalaya, Mizoram, Tripura, Manipur, Nagaland, Arunachal Pradesh, Sikkim, Chandigarh, Puducherry, etc.)

Sheet Notes & Verification
B2: Open Items and Verification Checklist
B3: Carried forward from the source calculator and extended. None of these is cleared. Work through them before the workbook is used to quote a client.
B5: Item | C5: Status | D5: What has to be done
B6: Two pricing blocks in the source file disagree | C6: CONFLICT | D6: The original tab carried a formula-driven block (total ₹20,465) and a hardcoded block (total ₹19,261). They differ on the FiLLiP fee, professional fee, franking and DSC, and the hardcoded block omitted Form 3 and had not followed the capital input. This calculator rebuilds the formula-driven block. Confirm that is the intended price.
B7: Professional fee — ₹3,499 or ₹3,950 | C7: CONFLICT | D7: Set the intended figure at C12 on the Calculator. A capital-based fee card can be built if a scale exists.
B8: Franking / notary — ₹1,799 or ₹1,950 | C8: CONFLICT | D8: Set the intended figure at C33 on the Calculator.
B9: Karnataka stamp duty | C9: CONFLICT | D9: The source state table carried a flat ₹500. The 'Stamp duty' tab gives ₹5,000 up to ₹10 lakh, then ₹1,000 for every further ₹5 lakh. The calculator applies the latter. Resolve against the Karnataka schedule.
B10: Arunachal Pradesh stamp duty | C10: CONFLICT | D10: The source state table carried 1% with no cap, described as taken from CAA's own calculator and unverified. The 'Stamp duty' tab gives no figure. The calculator returns "verify". Obtain the rate.
B11: Delhi stamp duty | C11: LIKELY RESOLVED | D11: The earlier "1% capped ₹5,000 vs approximately ₹200" conflict appears to be a floor-versus-rate confusion: the tab gives 1% with a ₹200 minimum and a ₹5,000 cap, which accommodates both figures. The calculator now applies a minimum as well as a cap. Confirm against the Delhi schedule.
B12: Rajasthan and Telangana rates | C12: AMBIGUOUS | D12: The source gives ranges (0.5%–1% and ₹100–₹300). The table applies the higher end in each case, which over-states rather than under-states. Resolve.
B13: Thirteen States and UTs carry no figure | C13: NO DATA | D13: The source groups the north-eastern States and several UTs together without an amount. Those rows are coded VERIFY and the calculator returns "verify" rather than a number. Populate them as rates are confirmed.
B14: MCA fee bands | C14: UNVERIFIED | D14: Secondary-sourced, August 2026. Confirm once against the MCA fee calculator, then update the status column on the MCA Fees LLP tab.
B15: DPIN / DIN | C15: OPEN | D15: Confirm whether DPIN for the first two designated partners is absorbed in the FiLLiP fee or payable at ₹500 each. The calculator has a separate input (C9) defaulting to nil.
B16: PAN and TAN — ₹143 | C16: UNVERIFIED | D16: Confirm the current charge on the MCA payment screen.
... B18: Pure-agent recovery | C18: PRACTICE POINT | D18: Rule 33 of the CGST Rules, 2017 requires recovery at the exact amount. Rounding a statutory recovery up makes the whole line taxable. Invoice from the challan, not from this estimate.
