Workbook
Name StateList: 'Stamp Duty'!$B$8:$B$42

Sheet Calculator
B2: Incorporation Cost Calculator — MCA Filing Fee + State Stamp Duty
B3: Rule 12, Companies (Registration Offices and Fees) Rules, 2014 (Table of Fees) and the State Stamp Acts | All amounts in Indian Rupees
B4: Cells in blue type on a yellow fill are inputs — edit those only. Every other figure is computed; do not overwrite.
B5: INPUTS
B6: Authorised Share Capital (Rs.) | C6: 1500000
B7: Company Category | C7: OPC / Small Company
B8: State / Union Territory of Registered Office | C8: Haryana
B9: Is this a Section 8 company? | C9: No
B10: Nil-fee threshold for incorporation (Rs.) | C10: 1500000
B11: Include name reservation fee (SPICe+ Part A / RUN)? | C11: Yes
B12: Number of Digital Signature Certificates required | C12: 2
B13: Professional fee — Company Avenue Advisory (Rs.) | C13: 3499
B14: Helper — fee column offset on 'MCA Fees' (0 = general; 3 = OPC / Small) | C14: =IF($C$7="OPC / Small Company",3,0) -> 3
B15: Helper — State row index on 'Stamp Duty' | C15: =MATCH($C$8,StateList,0) -> 13
B17: A. MCA STATUTORY FEE — computed per Rule 12, Table of Fees | D17: Category
B18: Registration fee on Memorandum of Association | C18: =IF($C$6<=$C$10,0,IF(AND($C$7="OPC / Small Company",$C$6<=5000000),2000+200*ROUNDUP(MAX(0,$C$6-1000000)/10000,0),36000+MIN(25000000,300*ROUNDUP(MAX(0,MIN($C$6,5000000)-1000000)/10000,0)+100*ROUNDUP(MAX(0,MIN($C$6,10000000)-5000000)/10000,0)+75*ROUNDUP(MAX(0,$C$6-10000000)/10000,0)))) -> 0 | D18: MCA Fees | E18: Table A, item 1(b) / 2(b)
B19: Filing fee — E-Form INC-32 (SPICe+) & Articles of Association | C19: =IF($C$6<=$C$10,0,IF($C$6<=100000,200,IF($C$6<500000,300,IF($C$6<2500000,400,IF($C$6<10000000,500,600))))) -> 0 | D19: MCA Fees | E19: Table A, item 5
B20: Sub-total — MCA statutory fee | C20: =C18+C19 -> 0 | D20: MCA Fees
B21: Control — variance against the published MCA slab table (at listed slabs only) | C21: =IF(ISNUMBER(MATCH($C$6,'MCA Fees'!$B$8:$B$32,0)),INDEX('MCA Fees'!$C$8:$H$32,MATCH($C$6,'MCA Fees'!$B$8:$B$32,0),1+$C$14)+INDEX('MCA Fees'!$C$8:$H$32,MATCH($C$6,'MCA Fees'!$B$8:$B$32,0),2+$C$14)-$C$20,"capital is not a listed slab — no control available") -> 0 | E21: Nil variance = engine agrees with the published table
B23: B. STATE STAMP DUTY
B24: Stamp duty on e-Form INC-32 (SPICe+) | C24: =IF(INDEX('Stamp Duty'!$N$8:$N$42,$C$15)="VERIFY","verify",INDEX('Stamp Duty'!$C$8:$C$42,$C$15)) -> 15 | D24: Stamp Duty | E24: ="AOA rule: "&INDEX('Stamp Duty'!$M$8:$M$42,$C$15) -> AOA rule: Rs. 60 if authorised capital up to Rs. 1,00,000; Rs. 120 if above
B25: Stamp duty on Memorandum of Association | C25: =IF(INDEX('Stamp Duty'!$E$8:$E$42,$C$15)="NA","verify",IF(AND($C$9="Yes",INDEX('Stamp Duty'!$N$8:$N$42,$C$15)="NIL"),0,IF(AND($C$9="Yes",INDEX('Stamp Duty'!$N$8:$N$42,$C$15)="VERIFY"),"verify",INDEX('Stamp Duty'!$D$8:$D$42,$C$15)))) -> 60 | D25: Stamp Duty
B26: Stamp duty on Articles of Association | C26: =IF(AND($C$9="Yes",INDEX('Stamp Duty'!$N$8:$N$42,$C$15)="NIL"),0,IF(AND($C$9="Yes",INDEX('Stamp Duty'!$N$8:$N$42,$C$15)="VERIFY"),"verify",INDEX('Stamp Duty'!$O$8:$O$42,$C$15))) -> 120 | D26: Stamp Duty
B27: Sub-total — State stamp duty | C27: =IF(AND(ISNUMBER(C24),ISNUMBER(C25),ISNUMBER(C26)),C24+C25+C26,"verify") -> 195 | D27: Stamp Duty
B29: C. OTHER STATUTORY CHARGES
B30: PAN/TAN | C30: 143 | D30: MCA Fees
B31: Name reservation (SPICe+ Part A / RUN) — Rs. 1,000 | C31: =IF($C$11="Yes",1000,0) -> 1000 | D31: MCA Fees | E31: Table of Fees, item II, note (1)
B32: Sub-total — other statutory charges | C32: =+C31+C30 -> 1143 | D32: MCA Fees
B34: D. DIGITAL SIGNATURE CERTIFICATES (DSC)
B35: Number of DSCs required (per input above) | C35: =$C$12 -> 2
B36: Cost per DSC — Class 3, two-year validity (Rs.) | C36: 2000 | E36: Vendor-quoted rate — not a statutory charge. Update to the actual certifying-authority invoice.
B37: Sub-total — DSC cost | C37: =$C$35*$C$36 -> 4000
B39: E. PROFESSIONAL FEES
B40: Professional fee — incorporation engagement | C40: =$C$13 -> 3499 | E40: As quoted to the client; taken from the input block.
B42: Sub-total — professional fees | C42: =$C$40+$C$41 -> 3499
B44: F. GOODS AND SERVICES TAX
B45: Taxable value — professional fees and DSC (D + E) | C45: =$C$37+$C$42 -> 7499
B46: GST rate | C46: 0.18 | E46: SAC 998222 — 18%. Intra-State: CGST 9% + SGST 9%. Inter-State: IGST 18%.
B47: GST amount | C47: =ROUND($C$45*$C$46,0) -> 1350
B48: Memo — GST is not charged on Sections A to C | C48: pure agent | E48: MCA fees and stamp duty recovered at actuals are excluded from the value of supply under Rule 33 of the CGST Rules, 2017, subject to the pure-agent conditions being met and the disbursement being separately indicated on the invoice.
...

Sheet MCA Fees
B2: MCA Filing Fees for Incorporation of a Company having Share Capital
B3: E-Form INC-32 (SPICe+), Memorandum of Association & Articles of Association | Amounts in Indian Rupees
B6: Authorised Capital (₹) | C6: Company Other than OPC / Small Company | F6: OPC / Small Company | J6: Reconciliation to the Statutory Formula (Rule 12)
C7: Memorandum of Association | D7: E-Form INC-32 (SPICe+) & AOA | E7: Total | F7: Memorandum of Association | G7: E-Form INC-32 (SPICe+) & AOA | H7: Total | J7: Rule 12 — MOA (General) | K7: Rule 12 — MOA (OPC/Small) | L7: Rule 12 — INC-32 & AOA | M7: Variance General | N7: Variance OPC/Small
B8: 100000 | C8: 0 | D8: 0 | E8: =C8+D8 -> 0 | F8: 0 | G8: 0 | H8: =F8+G8 -> 0 | J8: =IF($B8<=Calculator!$C$10,0,36000+MIN(25000000,300*ROUNDUP(MAX(0,MIN($B8,5000000)-1000000)/10000,0)+100*ROUNDUP(MAX(0,MIN($B8,10000000)-5000000)/10000,0)+75*ROUNDUP(MAX(0,$B8-10000000)/10000,0))) -> 0 | K8: =IF($B8<=Calculator!$C$10,0,IF($B8<=5000000,2000+200*ROUNDUP(MAX(0,$B8-1000000)/10000,0),J8)) -> 0 | L8: =IF($B8<=Calculator!$C$10,0,IF($B8<=100000,200,IF($B8<500000,300,IF($B8<2500000,400,IF($B8<10000000,500,600))))) -> 0 | M8: =E8-J8-L8 -> 0 | N8: =H8-K8-L8 -> 0
B9: 200000 | C9: 0 | D9: 0 | E9: =C9+D9 -> 0 | F9: 0 | G9: 0 | H9: =F9+G9 -> 0 | J9: =IF($B9<=Calculator!$C$10,0,36000+MIN(25000000,300*ROUNDUP(MAX(0,MIN($B9,5000000)-1000000)/10000,0)+100*ROUNDUP(MAX(0,MIN($B9,10000000)-5000000)/10000,0)+75*ROUNDUP(MAX(0,$B9-10000000)/10000,0))) -> 0 | K9: =IF($B9<=Calculator!$C$10,0,IF($B9<=5000000,2000+200*ROUNDUP(MAX(0,$B9-1000000)/10000,0),J9)) -> 0 | L9: =IF($B9<=Calculator!$C$10,0,IF($B9<=100000,200,IF($B9<500000,300,IF($B9<2500000,400,IF($B9<10000000,500,600))))) -> 0 | M9: =E9-J9-L9 -> 0 | N9: =H9-K9-L9 -> 0
B10: 300000 | C10: 0 | D10: 0 | E10: =C10+D10 -> 0 | F10: 0 | G10: 0 | H10: =F10+G10 -> 0 | J10: =IF($B10<=Calculator!$C$10,0,36000+MIN(25000000,300*ROUNDUP(MAX(0,MIN($B10,5000000)-1000000)/10000,0)+100*ROUNDUP(MAX(0,MIN($B10,10000000)-5000000)/10000,0)+75*ROUNDUP(MAX(0,$B10-10000000)/10000,0))) -> 0 | K10: =IF($B10<=Calculator!$C$10,0,IF($B10<=5000000,2000+200*ROUNDUP(MAX(0,$B10-1000000)/10000,0),J10)) -> 0 | L10: =IF($B10<=Calculator!$C$10,0,IF($B10<=100000,200,IF($B10<500000,300,IF($B10<2500000,400,IF($B10<10000000,500,600))))) -> 0 | M10: =E10-J10-L10 -> 0 | N10: =H10-K10-L10 -> 0
B11: 400000 | C11: 0 | D11: 0 | E11: =C11+D11 -> 0 | F11: 0 | G11: 0 | H11: =F11+G11 -> 0 | J11: =IF($B11<=Calculator!$C$10,0,36000+MIN(25000000,300*ROUNDUP(MAX(0,MIN($B11,5000000)-1000000)/10000,0)+100*ROUNDUP(MAX(0,MIN($B11,10000000)-5000000)/10000,0)+75*ROUNDUP(MAX(0,$B11-10000000)/10000,0))) -> 0 | K11: =IF($B11<=Calculator!$C$10,0,IF($B11<=5000000,2000+200*ROUNDUP(MAX(0,$B11-1000000)/10000,0),J11)) -> 0 | L11: =IF($B11<=Calculator!$C$10,0,IF($B11<=100000,200,IF($B11<500000,300,IF($B11<2500000,400,IF($B11<10000000,500,600))))) -> 0 | M11: =E11-J11-L11 -> 0 | N11: =H11-K11-L11 -> 0
B12: 500000 | C12: 0 | D12: 0 | E12: =C12+D12 -> 0 | F12: 0 | G12: 0 | H12: =F12+G12 -> 0 | J12: =IF($B12<=Calculator!$C$10,0,36000+MIN(25000000,300*ROUNDUP(MAX(0,MIN($B12,5000000)-1000000)/10000,0)+100*ROUNDUP(MAX(0,MIN($B12,10000000)-5000000)/10000,0)+75*ROUNDUP(MAX(0,$B12-10000000)/10000,0))) -> 0 | K12: =IF($B12<=Calculator!$C$10,0,IF($B12<=5000000,2000+200*ROUNDUP(MAX(0,$B12-1000000)/10000,0),J12)) -> 0 | L12: =IF($B12<=Calculator!$C$10,0,IF($B12<=100000,200,IF($B12<500000,300,IF($B12<2500000,400,IF($B12<10000000,500,600))))) -> 0 | M12: =E12-J12-L12 -> 0 | N12: =H12-K12-L12 -> 0
B13: 600000 | C13: 0 | D13: 0 | E13: =C13+D13 -> 0 | F13: 0 | G13: 0 | H13: =F13+G13 -> 0 | J13: =IF($B13<=Calculator!$C$10,0,36000+MIN(25000000,300*ROUNDUP(MAX(0,MIN($B13,5000000)-1000000)/10000,0)+100*ROUNDUP(MAX(0,MIN($B13,10000000)-5000000)/10000,0)+75*ROUNDUP(MAX(0,$B13-10000000)/10000,0))) -> 0 | K13: =IF($B13<=Calculator!$C$10,0,IF($B13<=5000000,2000+200*ROUNDUP(MAX(0,$B13-1000000)/10000,0),J13)) -> 0 | L13: =IF($B13<=Calculator!$C$10,0,IF($B13<=100000,200,IF($B13<500000,300,IF($B13<2500000,400,IF($B13<10000000,500,600))))) -> 0 | M13: =E13-J13-L13 -> 0 | N13: =H13-K13-L13 -> 0
B14: 700000 | C14: 0 | D14: 0 | E14: =C14+D14 -> 0 | F14: 0 | G14: 0 | H14: =F14+G14 -> 0 | J14: =IF($B14<=Calculator!$C$10,0,36000+MIN(25000000,300*ROUNDUP(MAX(0,MIN($B14,5000000)-1000000)/10000,0)+100*ROUNDUP(MAX(0,MIN($B14,10000000)-5000000)/10000,0)+75*ROUNDUP(MAX(0,$B14-10000000)/10000,0))) -> 0 | K14: =IF($B14<=Calculator!$C$10,0,IF($B14<=5000000,2000+200*ROUNDUP(MAX(0,$B14-1000000)/10000,0),J14)) -> 0 | L14: =IF($B14<=Calculator!$C$10,0,IF($B14<=100000,200,IF($B14<500000,300,IF($B14<2500000,400,IF($B14<10000000,500,600))))) -> 0 | M14: =E14-J14-L14 -> 0 | N14: =H14-K14-L14 -> 0
B15: 1000000 | C15: 0 | D15: 0 | E15: =C15+D15 -> 0 | F15: 0 | G15: 0 | H15: =F15+G15 -> 0 | J15: =IF($B15<=Calculator!$C$10,0,36000+MIN(25000000,300*ROUNDUP(MAX(0,MIN($B15,5000000)-1000000)/10000,0)+100*ROUNDUP(MAX(0,MIN($B15,10000000)-5000000)/10000,0)+75*ROUNDUP(MAX(0,$B15-10000000)/10000,0))) -> 0 | K15: =IF($B15<=Calculator!$C$10,0,IF($B15<=5000000,2000+200*ROUNDUP(MAX(0,$B15-1000000)/10000,0),J15)) -> 0 | L15: =IF($B15<=Calculator!$C$10,0,IF($B15<=100000,200,IF($B15<500000,300,IF($B15<2500000,400,IF($B15<10000000,500,600))))) -> 0 | M15: =E15-J15-L15 -> 0 | N15: =H15-K15-L15 -> 0
B16: 1500000 | C16: 0 | D16: 0 | E16: =C16+D16 -> 0 | F16: 0 | G16: 0 | H16: =F16+G16 -> 0 | J16: =IF($B16<=Calculator!$C$10,0,36000+MIN(25000000,300*ROUNDUP(MAX(0,MIN($B16,5000000)-1000000)/10000,0)+100*ROUNDUP(MAX(0,MIN($B16,10000000)-5000000)/10000,0)+75*ROUNDUP(MAX(0,$B16-10000000)/10000,0))) -> 0 | K16: =IF($B16<=Calculator!$C$10,0,IF($B16<=5000000,2000+200*ROUNDUP(MAX(0,$B16-1000000)/10000,0),J16)) -> 0 | L16: =IF($B16<=Calculator!$C$10,0,IF($B16<=100000,200,IF($B16<500000,300,IF($B16<2500000,400,IF($B16<10000000,500,600))))) -> 0 | M16: =E16-J16-L16 -> 0 | N16: =H16-K16-L16 -> 0
B17: 2000000 | C17: 66000 | D17: 400 | E17: =C17+D17 -> 66400 | F17: 22000 | G17: 400 | H17: =F17+G17 -> 22400 | J17: =IF($B17<=Calculator!$C$10,0,36000+MIN(25000000,300*ROUNDUP(MAX(0,MIN($B17,5000000)-1000000)/10000,0)+100*ROUNDUP(MAX(0,MIN($B17,10000000)-5000000)/10000,0)+75*ROUNDUP(MAX(0,$B17-10000000)/10000,0))) -> 66000 | K17: =IF($B17<=Calculator!$C$10,0,IF($B17<=5000000,2000+200*ROUNDUP(MAX(0,$B17-1000000)/10000,0),J17)) -> 22000 | L17: =IF($B17<=Calculator!$C$10,0,IF($B17<=100000,200,IF($B17<500000,300,IF($B17<2500000,400,IF($B17<10000000,500,600))))) -> 400 | M17: =E17-J17-L17 -> 0 | N17: =H17-K17-L17 -> 0
B18: 2500000 | C18: 81000 | D18: 500 | E18: =C18+D18 -> 81500 | F18: 32000 | G18: 500 | H18: =F18+G18 -> 32500 | J18: =IF($B18<=Calculator!$C$10,0,36000+MIN(25000000,300*ROUNDUP(MAX(0,MIN($B18,5000000)-1000000)/10000,0)+100*ROUNDUP(MAX(0,MIN($B18,10000000)-5000000)/10000,0)+75*ROUNDUP(MAX(0,$B18-10000000)/10000,0))) -> 81000 | K18: =IF($B18<=Calculator!$C$10,0,IF($B18<=5000000,2000+200*ROUNDUP(MAX(0,$B18-1000000)/10000,0),J18)) -> 32000 | L18: =IF($B18<=Calculator!$C$10,0,IF($B18<=100000,200,IF($B18<500000,300,IF($B18<2500000,400,IF($B18<10000000,500,600))))) -> 500 | M18: =E18-J18-L18 -> 0 | N18: =H18-K18-L18 -> 0
B19: 3000000 | C19: 96000 | D19: 500 | E19: =C19+D19 -> 96500 | F19: 42000 | G19: 500 | H19: =F19+G19 -> 42500 | J19: =IF($B19<=Calculator!$C$10,0,36000+MIN(25000000,300*ROUNDUP(MAX(0,MIN($B19,5000000)-1000000)/10000,0)+100*ROUNDUP(MAX(0,MIN($B19,10000000)-5000000)/10000,0)+75*ROUNDUP(MAX(0,$B19-10000000)/10000,0))) -> 96000 | K19: =IF($B19<=Calculator!$C$10,0,IF($B19<=5000000,2000+200*ROUNDUP(MAX(0,$B19-1000000)/10000,0),J19)) -> 42000 | L19: =IF($B19<=Calculator!$C$10,0,IF($B19<=100000,200,IF($B19<500000,300,IF($B19<2500000,400,IF($B19<10000000,500,600))))) -> 500 | M19: =E19-J19-L19 -> 0 | N19: =H19-K19-L19 -> 0
... B32: 50000000 | C32: 506000 | D32: 600 | E32: =C32+D32 -> 506600 | F32: 506000 | G32: 600 | H32: =F32+G32 -> 506600 | J32: =IF($B32<=Calculator!$C$10,0,36000+MIN(25000000,300*ROUNDUP(MAX(0,MIN($B32,5000000)-1000000)/10000,0)+100*ROUNDUP(MAX(0,MIN($B32,10000000)-5000000)/10000,0)+75*ROUNDUP(MAX(0,$B32-10000000)/10000,0))) -> 506000 | K32: =IF($B32<=Calculator!$C$10,0,IF($B32<=5000000,2000+200*ROUNDUP(MAX(0,$B32-1000000)/10000,0),J32)) -> 506000 | L32: =IF($B32<=Calculator!$C$10,0,IF($B32<=100000,200,IF($B32<500000,300,IF($B32<2500000,400,IF($B32<10000000,500,600))))) -> 600 | M32: =E32-J32-L32 -> 0 | N32: =H32-K32-L32 -> 0
B34: The INC-32 & AOA column is the combined fee of E-Form INC-32 (SPICe+) and the AOA. E-Form INC-32 itself carries a fee of Rs. 500; the AOA fee follows the share capital slab.
B35: Source: MCA fee table supplied by user, last updated 09.04.2024. Total columns computed as MOA + (INC-32 & AOA).
B36: RESOLVED — the jump at Rs. 60,00,000 in the OPC / Small Company table (Rs. 82,500 to Rs. 1,66,500) is correct. Table A, item 1(b) confines the concessional OPC / small company scale to nominal capital between Rs. 10,00,000 and Rs. 50,00,000. Above Rs. 50,00,000 there is no concessional rate and item 2(b) governs, so the two columns converge. This was flagged for verification in the earlier version and is now closed.
B37: The Variance columns must read nil on every row. A non-nil figure means the published table and the statutory formula disagree at that slab and the row should be investigated before the workbook is relied on.

Sheet Stamp Duty
B2: State-wise Stamp Duty on Incorporation Documents
B3: Companies HAVING share capital, other than Section 8 | Duty computed at the authorised capital entered on the 'Calculator' sheet
B7: State / Union Territory | C7: Duty on e-Form (₹) | D7: Duty on MOA (₹) | E7: AOA Rule | F7: P1 | G7: P2 | H7: Rate | I7: Minimum | J7: Maximum | K7: Block Size | L7: Per Block | M7: AOA Rule as Stated in Source | N7: Section 8 Treatment | O7: AOA Duty at Entered Capital | P7: Total Stamp Duty at Entered Capital
B8: Andaman and Nicobar Islands | C8: 20 | D8: 200 | E8: FLAT | F8: 300 | G8: 0 | H8: 0 | I8: 0 | J8: 0 | K8: 0 | L8: 0 | M8: Flat Rs. 300 | N8: NIL | O8: =IF($E8="NA","verify",IF($E8="FLAT",$F8,IF($E8="SLAB1L",IF(Calculator!$C$6<=100000,$F8,$G8),IF($E8="PCT",MIN(MAX(Calculator!$C$6*$H8,$I8),$J8),IF($E8="BLOCK",MIN(CEILING(Calculator!$C$6/$K8,1)*$L8,$J8),IF($E8="KERALA",IF(Calculator!$C$6<=1000000,2000,IF(Calculator!$C$6<=2500000,5000,Calculator!$C$6*0.005)),"verify")))))) -> 300 | P8: =IF(ISNUMBER(O8),C8+D8+O8,"verify") -> 520
B9: Andhra Pradesh | C9: 20 | D9: 500 | E9: PCT | F9: 0 | G9: 0 | H9: 0.0015 | I9: 1000 | J9: 500000 | K9: 0 | L9: 0 | M9: 0.15% of authorised capital, min Rs. 1,000, max Rs. 5,00,000 | N9: SAME | O9: =IF($E9="NA","verify",IF($E9="FLAT",$F9,IF($E9="SLAB1L",IF(Calculator!$C$6<=100000,$F9,$G9),IF($E9="PCT",MIN(MAX(Calculator!$C$6*$H9,$I9),$J9),IF($E9="BLOCK",MIN(CEILING(Calculator!$C$6/$K9,1)*$L9,$J9),IF($E9="KERALA",IF(Calculator!$C$6<=1000000,2000,IF(Calculator!$C$6<=2500000,5000,Calculator!$C$6*0.005)),"verify")))))) -> 2250 | P9: =IF(ISNUMBER(O9),C9+D9+O9,"verify") -> 2770
B10: Arunachal Pradesh | C10: 10 | D10: 200 | E10: FLAT | F10: 500 | G10: 0 | H10: 0 | I10: 0 | J10: 0 | K10: 0 | L10: 0 | M10: Flat Rs. 500 | N10: SAME | O10: =IF($E10="NA","verify",IF($E10="FLAT",$F10,IF($E10="SLAB1L",IF(Calculator!$C$6<=100000,$F10,$G10),IF($E10="PCT",MIN(MAX(Calculator!$C$6*$H10,$I10),$J10),IF($E10="BLOCK",MIN(CEILING(Calculator!$C$6/$K10,1)*$L10,$J10),IF($E10="KERALA",IF(Calculator!$C$6<=1000000,2000,IF(Calculator!$C$6<=2500000,5000,Calculator!$C$6*0.005)),"verify")))))) -> 500 | P10: =IF(ISNUMBER(O10),C10+D10+O10,"verify") -> 710
B11: Assam | C11: 15 | D11: 200 | E11: FLAT | F11: 310 | G11: 0 | H11: 0 | I11: 0 | J11: 0 | K11: 0 | L11: 0 | M11: Flat Rs. 310 | N11: SAME | O11: =IF($E11="NA","verify",IF($E11="FLAT",$F11,IF($E11="SLAB1L",IF(Calculator!$C$6<=100000,$F11,$G11),IF($E11="PCT",MIN(MAX(Calculator!$C$6*$H11,$I11),$J11),IF($E11="BLOCK",MIN(CEILING(Calculator!$C$6/$K11,1)*$L11,$J11),IF($E11="KERALA",IF(Calculator!$C$6<=1000000,2000,IF(Calculator!$C$6<=2500000,5000,Calculator!$C$6*0.005)),"verify")))))) -> 310 | P11: =IF(ISNUMBER(O11),C11+D11+O11,"verify") -> 525
B12: Bihar | C12: 20 | D12: 500 | E12: PCT | F12: 0 | G12: 0 | H12: 0.0015 | I12: 1000 | J12: 500000 | K12: 0 | L12: 0 | M12: Higher of Rs. 1,000 or 0.15% of authorised capital, max Rs. 5,00,000 | N12: NIL | O12: =IF($E12="NA","verify",IF($E12="FLAT",$F12,IF($E12="SLAB1L",IF(Calculator!$C$6<=100000,$F12,$G12),IF($E12="PCT",MIN(MAX(Calculator!$C$6*$H12,$I12),$J12),IF($E12="BLOCK",MIN(CEILING(Calculator!$C$6/$K12,1)*$L12,$J12),IF($E12="KERALA",IF(Calculator!$C$6<=1000000,2000,IF(Calculator!$C$6<=2500000,5000,Calculator!$C$6*0.005)),"verify")))))) -> 2250 | P12: =IF(ISNUMBER(O12),C12+D12+O12,"verify") -> 2770
B13: Chandigarh | C13: 3 | D13: 500 | E13: FLAT | F13: 1000 | G13: 0 | H13: 0 | I13: 0 | J13: 0 | K13: 0 | L13: 0 | M13: Flat Rs. 1,000 | N13: NIL | O13: =IF($E13="NA","verify",IF($E13="FLAT",$F13,IF($E13="SLAB1L",IF(Calculator!$C$6<=100000,$F13,$G13),IF($E13="PCT",MIN(MAX(Calculator!$C$6*$H13,$I13),$J13),IF($E13="BLOCK",MIN(CEILING(Calculator!$C$6/$K13,1)*$L13,$J13),IF($E13="KERALA",IF(Calculator!$C$6<=1000000,2000,IF(Calculator!$C$6<=2500000,5000,Calculator!$C$6*0.005)),"verify")))))) -> 1000 | P13: =IF(ISNUMBER(O13),C13+D13+O13,"verify") -> 1503
B14: Chhattisgarh | C14: 10 | D14: 500 | E14: PCT | F14: 0 | G14: 0 | H14: 0.0015 | I14: 1000 | J14: 500000 | K14: 0 | L14: 0 | M14: Higher of Rs. 1,000 or 0.15% of authorised capital, max Rs. 5,00,000 | N14: NIL | O14: =IF($E14="NA","verify",IF($E14="FLAT",$F14,IF($E14="SLAB1L",IF(Calculator!$C$6<=100000,$F14,$G14),IF($E14="PCT",MIN(MAX(Calculator!$C$6*$H14,$I14),$J14),IF($E14="BLOCK",MIN(CEILING(Calculator!$C$6/$K14,1)*$L14,$J14),IF($E14="KERALA",IF(Calculator!$C$6<=1000000,2000,IF(Calculator!$C$6<=2500000,5000,Calculator!$C$6*0.005)),"verify")))))) -> 2250 | P14: =IF(ISNUMBER(O14),C14+D14+O14,"verify") -> 2760
B15: Dadra and Nagar Haveli | C15: 1 | D15: 15 | E15: FLAT | F15: 25 | G15: 0 | H15: 0 | I15: 0 | J15: 0 | K15: 0 | L15: 0 | M15: Flat Rs. 25 | N15: NIL | O15: =IF($E15="NA","verify",IF($E15="FLAT",$F15,IF($E15="SLAB1L",IF(Calculator!$C$6<=100000,$F15,$G15),IF($E15="PCT",MIN(MAX(Calculator!$C$6*$H15,$I15),$J15),IF($E15="BLOCK",MIN(CEILING(Calculator!$C$6/$K15,1)*$L15,$J15),IF($E15="KERALA",IF(Calculator!$C$6<=1000000,2000,IF(Calculator!$C$6<=2500000,5000,Calculator!$C$6*0.005)),"verify")))))) -> 25 | P15: =IF(ISNUMBER(O15),C15+D15+O15,"verify") -> 41
B16: Daman and Diu | C16: 20 | D16: 150 | E16: BLOCK | F16: 0 | G16: 0 | H16: 0 | I16: 0 | J16: 1000000000 | K16: 500000 | L16: 1000 | M16: Rs. 1,000 for every Rs. 5,00,000 of authorised capital or part thereof | N16: NIL | O16: =IF($E16="NA","verify",IF($E16="FLAT",$F16,IF($E16="SLAB1L",IF(Calculator!$C$6<=100000,$F16,$G16),IF($E16="PCT",MIN(MAX(Calculator!$C$6*$H16,$I16),$J16),IF($E16="BLOCK",MIN(CEILING(Calculator!$C$6/$K16,1)*$L16,$J16),IF($E16="KERALA",IF(Calculator!$C$6<=1000000,2000,IF(Calculator!$C$6<=2500000,5000,Calculator!$C$6*0.005)),"verify")))))) -> 3000 | P16: =IF(ISNUMBER(O16),C16+D16+O16,"verify") -> 3170
B17: Delhi | C17: 10 | D17: 200 | E17: PCT | F17: 0 | G17: 0 | H17: 0.0015 | I17: 0 | J17: 2500000 | K17: 0 | L17: 0 | M17: 0.15% of authorised capital, max Rs. 25,00,000 | N17: NIL | O17: =IF($E17="NA","verify",IF($E17="FLAT",$F17,IF($E17="SLAB1L",IF(Calculator!$C$6<=100000,$F17,$G17),IF($E17="PCT",MIN(MAX(Calculator!$C$6*$H17,$I17),$J17),IF($E17="BLOCK",MIN(CEILING(Calculator!$C$6/$K17,1)*$L17,$J17),IF($E17="KERALA",IF(Calculator!$C$6<=1000000,2000,IF(Calculator!$C$6<=2500000,5000,Calculator!$C$6*0.005)),"verify")))))) -> 2250 | P17: =IF(ISNUMBER(O17),C17+D17+O17,"verify") -> 2460
B18: Goa | C18: 50 | D18: 150 | E18: BLOCK | F18: 0 | G18: 0 | H18: 0 | I18: 0 | J18: 1000000000 | K18: 500000 | L18: 1000 | M18: Rs. 1,000 for every Rs. 5,00,000 of authorised capital or part thereof | N18: NIL | O18: =IF($E18="NA","verify",IF($E18="FLAT",$F18,IF($E18="SLAB1L",IF(Calculator!$C$6<=100000,$F18,$G18),IF($E18="PCT",MIN(MAX(Calculator!$C$6*$H18,$I18),$J18),IF($E18="BLOCK",MIN(CEILING(Calculator!$C$6/$K18,1)*$L18,$J18),IF($E18="KERALA",IF(Calculator!$C$6<=1000000,2000,IF(Calculator!$C$6<=2500000,5000,Calculator!$C$6*0.005)),"verify")))))) -> 3000 | P18: =IF(ISNUMBER(O18),C18+D18+O18,"verify") -> 3200
B19: Gujarat | C19: 20 | D19: 100 | E19: PCT | F19: 0 | G19: 0 | H19: 0.005 | I19: 0 | J19: 1500000 | K19: 0 | L19: 0 | M19: 0.5% of authorised capital, max Rs. 15,00,000 — cap raised from Rs. 5,00,000 by the Gujarat Stamp (Amendment) Act, 2025, Article 12 of Schedule I | N19: NIL | O19: =IF($E19="NA","verify",IF($E19="FLAT",$F19,IF($E19="SLAB1L",IF(Calculator!$C$6<=100000,$F19,$G19),IF($E19="PCT",MIN(MAX(Calculator!$C$6*$H19,$I19),$J19),IF($E19="BLOCK",MIN(CEILING(Calculator!$C$6/$K19,1)*$L19,$J19),IF($E19="KERALA",IF(Calculator!$C$6<=1000000,2000,IF(Calculator!$C$6<=2500000,5000,Calculator!$C$6*0.005)),"verify")))))) -> 7500 | P19: =IF(ISNUMBER(O19),C19+D19+O19,"verify") -> 7620
... B42: West Bengal | C42: 10 | D42: 60 | E42: FLAT | F42: 300 | G42: 0 | H42: 0 | I42: 0 | J42: 0 | K42: 0 | L42: 0 | M42: Flat Rs. 300 | N42: NIL | O42: =IF($E42="NA","verify",IF($E42="FLAT",$F42,IF($E42="SLAB1L",IF(Calculator!$C$6<=100000,$F42,$G42),IF($E42="PCT",MIN(MAX(Calculator!$C$6*$H42,$I42),$J42),IF($E42="BLOCK",MIN(CEILING(Calculator!$C$6/$K42,1)*$L42,$J42),IF($E42="KERALA",IF(Calculator!$C$6<=1000000,2000,IF(Calculator!$C$6<=2500000,5000,Calculator!$C$6*0.005)),"verify")))))) -> 300 | P42: =IF(ISNUMBER(O42),C42+D42+O42,"verify") -> 370
B44: Columns F to L are rule parameters driving the AOA computation — P1 is the flat or lower-slab amount, P2 the higher-slab amount where a Rs. 1,00,000 threshold applies. Where no statutory cap is stated in the source, Maximum is set to Rs. 1,00,00,00,000 so the cap does not bind.
B45: Section 8 treatment — NIL: the State exempts Section 8 companies from MOA and AOA stamp duty (duty on the e-Form remains payable). SAME: the source states the general rules also apply to Section 8 companies having share capital. VERIFY: the source is silent or the State is absent from the database.
B46: Source: MCA state-wise stamp duty database for eForm INC-2/INC-7/INC-29, MoA, AoA and SH-7, as reproduced at taxguru.in (published 28.11.2020). Rules stated for INC-2/INC-7/INC-29 have been applied to SPICe+ (INC-32) — confirm this mapping before client use. Sikkim and Ladakh do not appear in the source.
